<?xml version="1.0" ?>
<!-- =================================================================================== -->
<!-- |    This document was autogenerated by xacro from /home/keith/Documents/src/ros/dog_picker/src/dog_picker_description/urdf/dog_picker_description.xacro | -->
<!-- |    EDITING THIS FILE BY HAND IS NOT RECOMMENDED                                 | -->
<!-- =================================================================================== -->
<robot name="dog_picker" xmlns:xacro="http://www.ros.org/wiki/xacro">
  <!-- negative green is the joint axis in y... -->
  <!-- z is blue and x is red... -->
  <link name="base_link">
    <visual>
      <origin rpy="0 0 0" xyz="0 0 0.150"/>
      <geometry>
        <box size="0.09 0.1 0.032"/>
      </geometry>
      <material name="DimWhite">
        <color rgba="0.9 0.9 0.9 1.0"/>
      </material>
    </visual>
  </link>
  <joint name="robotis_part_6" type="fixed">
    <origin rpy="0 0 0" xyz="0.045 0 0.150"/>
    <parent link="base_link"/>
    <child link="neck_link"/>
  </joint>
  <link name="neck_link">
    <visual>
      <origin rpy="0 0 0" xyz="0.0195 0 0.0035"/>
      <geometry>
        <box size="0.039 0.048  0.039 "/>
      </geometry>
      <material name="DimWhite">
        <color rgba="0.9 0.9 0.9 1.0"/>
      </material>
    </visual>
  </link>
  <joint name="S1_6" type="fixed">
    <origin rpy="3.14159 0 0" xyz="0.027 0.021 0.0125"/>
    <parent link="neck_link"/>
    <child link="S-B_6_link"/>
  </joint>
  <link name="S-B_6_link">
    <visual>
      <origin rpy="0 0 0" xyz="0 0 0"/>
      <geometry>
        <sphere radius="0.004"/>
      </geometry>
      <material name="Green">
        <color rgba="0 0.5 0 1.0"/>
      </material>
    </visual>
  </link>
  <joint name="dynamixel_AX12_6_joint" type="revolute">
    <!--origin of whole dynamixel is at the center of the round part visible on the servo which is the joint -->
    <origin rpy="0 0 0" xyz="0 0 0"/>
    <!-- negative green is the joint axis... -->
    <axis xyz="0 -1 0"/>
    <limit effort="1000" lower="-2.61799166667" upper="2.61799166667" velocity="0.5"/>
    <parent link="S-B_6_link"/>
    <child link="dynamixel_AX12_6_link"/>
  </joint>
  <link name="dynamixel_AX12_6_link">
    <!---rviz -->
    <visual>
      <!--link origin is a delta from the joint to the center of the servo box-->
      <origin rpy="0 0 0" xyz="0 0.02 -0.0135"/>
      <geometry>
        <!-- <mesh filename="package://pi_tb_description/meshes/ax12_box.${MESH_EXT}" scale="${M_SCALE} ${M_SCALE} ${M_SCALE}"/> -->
        <box size="0.032 0.04 0.05"/>
      </geometry>
      <material name="black"/>
    </visual>
    <!---gazebo section needs work http://wiki.ros.org/MeshLab http://en.wikipedia.org/wiki/List_of_moment_of_inertia_tensors   
      <inertial>
        <mass value="0.00001" />
        <inertia ixx="1.0" ixy="0.0" ixz="0.0"
          iyy="1.0" iyz="0.0"
          izz="1.0" />
      </inertial>
      <collision>
        <origin xyz="0.0 0.0 -0.0045" rpy="0 0 0" />
        <geometry>
          <box size="0.025 0.038 0.009"/>
        </geometry>
      </collision>
-->
  </link>
  <joint name="S1_17" type="fixed">
    <origin rpy="-1.570795 0 1.570795" xyz="0 0.02 -0.0415"/>
    <parent link="dynamixel_AX12_6_link"/>
    <child link="S-B_17_link"/>
  </joint>
  <link name="S-B_17_link">
    <visual>
      <origin rpy="0 0 0" xyz="0 0 0"/>
      <geometry>
        <sphere radius="0.004"/>
      </geometry>
      <material name="Green">
        <color rgba="0 0.5 0 1.0"/>
      </material>
    </visual>
  </link>
  <joint name="dynamixel_AX12_17_joint" type="revolute">
    <!--origin of whole dynamixel is at the center of the round part visible on the servo which is the joint -->
    <origin rpy="0 0 0" xyz="0 0 0"/>
    <!-- negative green is the joint axis... -->
    <axis xyz="0 -1 0"/>
    <limit effort="1000" lower="-2.61799166667" upper="2.61799166667" velocity="0.5"/>
    <parent link="S-B_17_link"/>
    <child link="dynamixel_AX12_17_link"/>
  </joint>
  <link name="dynamixel_AX12_17_link">
    <!---rviz -->
    <visual>
      <!--link origin is a delta from the joint to the center of the servo box-->
      <origin rpy="0 0 0" xyz="0 0.02 -0.0135"/>
      <geometry>
        <!-- <mesh filename="package://pi_tb_description/meshes/ax12_box.${MESH_EXT}" scale="${M_SCALE} ${M_SCALE} ${M_SCALE}"/> -->
        <box size="0.032 0.04 0.05"/>
      </geometry>
      <material name="black"/>
    </visual>
    <!---gazebo section needs work http://wiki.ros.org/MeshLab http://en.wikipedia.org/wiki/List_of_moment_of_inertia_tensors   
      <inertial>
        <mass value="0.00001" />
        <inertia ixx="1.0" ixy="0.0" ixz="0.0"
          iyy="1.0" iyz="0.0"
          izz="1.0" />
      </inertial>
      <collision>
        <origin xyz="0.0 0.0 -0.0045" rpy="0 0 0" />
        <geometry>
          <box size="0.025 0.038 0.009"/>
        </geometry>
      </collision>
-->
  </link>
  <joint name="robotis_part_1" type="fixed">
    <origin rpy="0 0 0" xyz="-0.045 0 0.150"/>
    <parent link="base_link"/>
    <child link="butt_link"/>
  </joint>
  <link name="butt_link">
    <visual>
      <origin rpy="0 0 0" xyz="-0.0225 0 0"/>
      <geometry>
        <box size="0.035 0.048  0.024 "/>
      </geometry>
      <material name="DimWhite">
        <color rgba="0.9 0.9 0.9 1.0"/>
      </material>
    </visual>
  </link>
  <joint name="S1_1" type="fixed">
    <origin rpy="0 1.570795 0" xyz="-0.0355 -0.02 0"/>
    <parent link="butt_link"/>
    <child link="S-B_1_link"/>
  </joint>
  <link name="S-B_1_link">
    <visual>
      <origin rpy="0 0 0" xyz="0 0 0"/>
      <geometry>
        <sphere radius="0.004"/>
      </geometry>
      <material name="Green">
        <color rgba="0 0.5 0 1.0"/>
      </material>
    </visual>
  </link>
  <joint name="dynamixel_AX12_1_joint" type="revolute">
    <!--origin of whole dynamixel is at the center of the round part visible on the servo which is the joint -->
    <origin rpy="0 0 0" xyz="0 0 0"/>
    <!-- negative green is the joint axis... -->
    <axis xyz="0 -1 0"/>
    <limit effort="1000" lower="-2.61799166667" upper="2.61799166667" velocity="0.5"/>
    <parent link="S-B_1_link"/>
    <child link="dynamixel_AX12_1_link"/>
  </joint>
  <link name="dynamixel_AX12_1_link">
    <!---rviz -->
    <visual>
      <!--link origin is a delta from the joint to the center of the servo box-->
      <origin rpy="0 0 0" xyz="0 0.02 -0.0135"/>
      <geometry>
        <!-- <mesh filename="package://pi_tb_description/meshes/ax12_box.${MESH_EXT}" scale="${M_SCALE} ${M_SCALE} ${M_SCALE}"/> -->
        <box size="0.032 0.04 0.05"/>
      </geometry>
      <material name="black"/>
    </visual>
    <!---gazebo section needs work http://wiki.ros.org/MeshLab http://en.wikipedia.org/wiki/List_of_moment_of_inertia_tensors   
      <inertial>
        <mass value="0.00001" />
        <inertia ixx="1.0" ixy="0.0" ixz="0.0"
          iyy="1.0" iyz="0.0"
          izz="1.0" />
      </inertial>
      <collision>
        <origin xyz="0.0 0.0 -0.0045" rpy="0 0 0" />
        <geometry>
          <box size="0.025 0.038 0.009"/>
        </geometry>
      </collision>
-->
  </link>
  <joint name="robotis_part_4" type="fixed">
    <origin rpy="1.570795 -1.570795 0.0" xyz="0.045 -0.0365 0.111"/>
    <parent link="base_link"/>
    <child link="dynamixel_AX12_4_link"/>
  </joint>
  <link name="dynamixel_AX12_4_link">
    <!---rviz -->
    <visual>
      <!--link origin is a delta from the joint to the center of the servo box-->
      <origin rpy="0 0 0" xyz="0 0.02 -0.0135"/>
      <geometry>
        <!-- <mesh filename="package://pi_tb_description/meshes/ax12_box.${MESH_EXT}" scale="${M_SCALE} ${M_SCALE} ${M_SCALE}"/> -->
        <box size="0.032 0.04 0.05"/>
      </geometry>
      <material name="Gray">
        <color rgba="0.1 0.1 0.1 1.0"/>
      </material>
    </visual>
  </link>
  <joint name="dynamixel_AX12_4_joint" type="revolute">
    <!--origin of whole dynamixel is at the center of the round part visible on the servo which is the joint -->
    <origin rpy="0 0 0" xyz="0 0 0"/>
    <axis xyz="0 -1 0"/>
    <limit effort="1000" lower="-2.61799166667" upper="2.61799166667" velocity="0.5"/>
    <parent link="dynamixel_AX12_4_link"/>
    <child link="S-B_4_link"/>
  </joint>
  <link name="S-B_4_link">
    <visual>
      <origin rpy="0 0 0" xyz="0 0 0"/>
      <geometry>
        <sphere radius="0.004"/>
      </geometry>
      <material name="Green">
        <color rgba="0 0.5 0 1.0"/>
      </material>
    </visual>
  </link>
  <joint name="S1_4" type="fixed">
    <origin rpy="-1.570795 0 1.570795 " xyz="-0.023 -0.021  0.02"/>
    <parent link="S-B_4_link"/>
    <child link="dynamixel_AX12_16_link"/>
  </joint>
  <link name="dynamixel_AX12_16_link">
    <!---rviz -->
    <visual>
      <!--link origin is a delta from the joint to the center of the servo box-->
      <origin rpy="0 0 0" xyz="0 0.02 -0.0135"/>
      <geometry>
        <!-- <mesh filename="package://pi_tb_description/meshes/ax12_box.${MESH_EXT}" scale="${M_SCALE} ${M_SCALE} ${M_SCALE}"/> -->
        <box size="0.032 0.04 0.05"/>
      </geometry>
      <material name="Gray">
        <color rgba="0.1 0.1 0.1 1.0"/>
      </material>
    </visual>
  </link>
  <joint name="dynamixel_AX12_16_joint" type="revolute">
    <!--origin of whole dynamixel is at the center of the round part visible on the servo which is the joint -->
    <origin rpy="0 0 0" xyz="0 0 0"/>
    <axis xyz="0 -1 0"/>
    <limit effort="1000" lower="-2.61799166667" upper="2.61799166667" velocity="0.5"/>
    <parent link="dynamixel_AX12_16_link"/>
    <child link="S-B_16_link"/>
  </joint>
  <link name="S-B_16_link">
    <visual>
      <origin rpy="0 0 0" xyz="0 0 0"/>
      <geometry>
        <sphere radius="0.004"/>
      </geometry>
      <material name="Green">
        <color rgba="0 0.5 0 1.0"/>
      </material>
    </visual>
  </link>
  <joint name="S1_16" type="fixed">
    <origin rpy="0 0 0" xyz="0 0.021 0.0305"/>
    <parent link="S-B_16_link"/>
    <child link="calf_link_8"/>
  </joint>
  <link name="calf_link_8">
    <visual>
      <origin rpy="0 0 0" xyz="0 0 0"/>
      <geometry>
        <box size="0.024  0.048 0.07"/>
      </geometry>
      <material name="DimWhite">
        <color rgba="0.9 0.9 0.9 1.0"/>
      </material>
    </visual>
  </link>
  <joint name="S1_8" type="fixed">
    <origin rpy="0 3.14159 0" xyz="0 -0.021 0.0305"/>
    <parent link="calf_link_8"/>
    <child link="S-B_8_link"/>
  </joint>
  <link name="S-B_8_link">
    <visual>
      <origin rpy="0 0 0" xyz="0 0 0"/>
      <geometry>
        <sphere radius="0.004"/>
      </geometry>
      <material name="Green">
        <color rgba="0 0.5 0 1.0"/>
      </material>
    </visual>
  </link>
  <joint name="dynamixel_AX12_8_joint" type="revolute">
    <!--origin of whole dynamixel is at the center of the round part visible on the servo which is the joint -->
    <origin rpy="0 0 0" xyz="0 0 0"/>
    <!-- negative green is the joint axis... -->
    <axis xyz="0 -1 0"/>
    <limit effort="1000" lower="-2.61799166667" upper="2.61799166667" velocity="0.5"/>
    <parent link="S-B_8_link"/>
    <child link="dynamixel_AX12_8_link"/>
  </joint>
  <link name="dynamixel_AX12_8_link">
    <!---rviz -->
    <visual>
      <!--link origin is a delta from the joint to the center of the servo box-->
      <origin rpy="0 0 0" xyz="0 0.02 -0.0135"/>
      <geometry>
        <!-- <mesh filename="package://pi_tb_description/meshes/ax12_box.${MESH_EXT}" scale="${M_SCALE} ${M_SCALE} ${M_SCALE}"/> -->
        <box size="0.032 0.04 0.05"/>
      </geometry>
      <material name="black"/>
    </visual>
    <!---gazebo section needs work http://wiki.ros.org/MeshLab http://en.wikipedia.org/wiki/List_of_moment_of_inertia_tensors   
      <inertial>
        <mass value="0.00001" />
        <inertia ixx="1.0" ixy="0.0" ixz="0.0"
          iyy="1.0" iyz="0.0"
          izz="1.0" />
      </inertial>
      <collision>
        <origin xyz="0.0 0.0 -0.0045" rpy="0 0 0" />
        <geometry>
          <box size="0.025 0.038 0.009"/>
        </geometry>
      </collision>
-->
  </link>
  <joint name="robotis_part_11" type="fixed">
    <origin rpy="1.570795 0.0 3.14159" xyz="0.039 0.0575 -0.04"/>
    <parent link="dynamixel_AX12_1_link"/>
    <child link="dynamixel_AX12_11_link"/>
  </joint>
  <link name="dynamixel_AX12_11_link">
    <!---rviz -->
    <visual>
      <!--link origin is a delta from the joint to the center of the servo box-->
      <origin rpy="0 0 0" xyz="0 0.02 -0.0135"/>
      <geometry>
        <!-- <mesh filename="package://pi_tb_description/meshes/ax12_box.${MESH_EXT}" scale="${M_SCALE} ${M_SCALE} ${M_SCALE}"/> -->
        <box size="0.032 0.04 0.05"/>
      </geometry>
      <material name="Gray">
        <color rgba="0.1 0.1 0.1 1.0"/>
      </material>
    </visual>
  </link>
  <joint name="dynamixel_AX12_11_joint" type="revolute">
    <!--origin of whole dynamixel is at the center of the round part visible on the servo which is the joint -->
    <origin rpy="0 0 0" xyz="0 0 0"/>
    <axis xyz="0 -1 0"/>
    <limit effort="1000" lower="-2.61799166667" upper="2.61799166667" velocity="0.5"/>
    <parent link="dynamixel_AX12_11_link"/>
    <child link="S-B_11_link"/>
  </joint>
  <link name="S-B_11_link">
    <visual>
      <origin rpy="0 0 0" xyz="0 0 0"/>
      <geometry>
        <sphere radius="0.004"/>
      </geometry>
      <material name="Green">
        <color rgba="0 0.5 0 1.0"/>
      </material>
    </visual>
  </link>
  <joint name="S1_11" type="fixed">
    <origin rpy="-1.570795 0 1.570795 " xyz="-0.023 -0.021  0.02"/>
    <parent link="S-B_11_link"/>
    <child link="dynamixel_AX12_13_link"/>
  </joint>
  <link name="dynamixel_AX12_13_link">
    <!---rviz -->
    <visual>
      <!--link origin is a delta from the joint to the center of the servo box-->
      <origin rpy="0 0 0" xyz="0 0.02 -0.0135"/>
      <geometry>
        <!-- <mesh filename="package://pi_tb_description/meshes/ax12_box.${MESH_EXT}" scale="${M_SCALE} ${M_SCALE} ${M_SCALE}"/> -->
        <box size="0.032 0.04 0.05"/>
      </geometry>
      <material name="Gray">
        <color rgba="0.1 0.1 0.1 1.0"/>
      </material>
    </visual>
  </link>
  <joint name="dynamixel_AX12_13_joint" type="revolute">
    <!--origin of whole dynamixel is at the center of the round part visible on the servo which is the joint -->
    <origin rpy="0 0 0" xyz="0 0 0"/>
    <axis xyz="0 -1 0"/>
    <limit effort="1000" lower="-2.61799166667" upper="2.61799166667" velocity="0.5"/>
    <parent link="dynamixel_AX12_13_link"/>
    <child link="S-B_13_link"/>
  </joint>
  <link name="S-B_13_link">
    <visual>
      <origin rpy="0 0 0" xyz="0 0 0"/>
      <geometry>
        <sphere radius="0.004"/>
      </geometry>
      <material name="Green">
        <color rgba="0 0.5 0 1.0"/>
      </material>
    </visual>
  </link>
  <joint name="S1_13" type="fixed">
    <origin rpy="0 0 0" xyz="0 0.021 0.0305"/>
    <parent link="S-B_13_link"/>
    <child link="calf_link_15"/>
  </joint>
  <link name="calf_link_15">
    <visual>
      <origin rpy="0 0 0" xyz="0 0 0"/>
      <geometry>
        <box size="0.024  0.048 0.07"/>
      </geometry>
      <material name="DimWhite">
        <color rgba="0.9 0.9 0.9 1.0"/>
      </material>
    </visual>
  </link>
  <joint name="S1_15" type="fixed">
    <origin rpy="0 3.14159 0" xyz="0 -0.021 0.0305"/>
    <parent link="calf_link_15"/>
    <child link="S-B_15_link"/>
  </joint>
  <link name="S-B_15_link">
    <visual>
      <origin rpy="0 0 0" xyz="0 0 0"/>
      <geometry>
        <sphere radius="0.004"/>
      </geometry>
      <material name="Green">
        <color rgba="0 0.5 0 1.0"/>
      </material>
    </visual>
  </link>
  <joint name="dynamixel_AX12_15_joint" type="revolute">
    <!--origin of whole dynamixel is at the center of the round part visible on the servo which is the joint -->
    <origin rpy="0 0 0" xyz="0 0 0"/>
    <!-- negative green is the joint axis... -->
    <axis xyz="0 -1 0"/>
    <limit effort="1000" lower="-2.61799166667" upper="2.61799166667" velocity="0.5"/>
    <parent link="S-B_15_link"/>
    <child link="dynamixel_AX12_15_link"/>
  </joint>
  <link name="dynamixel_AX12_15_link">
    <!---rviz -->
    <visual>
      <!--link origin is a delta from the joint to the center of the servo box-->
      <origin rpy="0 0 0" xyz="0 0.02 -0.0135"/>
      <geometry>
        <!-- <mesh filename="package://pi_tb_description/meshes/ax12_box.${MESH_EXT}" scale="${M_SCALE} ${M_SCALE} ${M_SCALE}"/> -->
        <box size="0.032 0.04 0.05"/>
      </geometry>
      <material name="black"/>
    </visual>
    <!---gazebo section needs work http://wiki.ros.org/MeshLab http://en.wikipedia.org/wiki/List_of_moment_of_inertia_tensors   
      <inertial>
        <mass value="0.00001" />
        <inertia ixx="1.0" ixy="0.0" ixz="0.0"
          iyy="1.0" iyz="0.0"
          izz="1.0" />
      </inertial>
      <collision>
        <origin xyz="0.0 0.0 -0.0045" rpy="0 0 0" />
        <geometry>
          <box size="0.025 0.038 0.009"/>
        </geometry>
      </collision>
-->
  </link>
  <joint name="robotis_part_5" type="fixed">
    <origin rpy="-1.570795 1.570795 0.0" xyz="0.045 0.0365 0.111"/>
    <parent link="base_link"/>
    <child link="dynamixel_AX12_5_link"/>
  </joint>
  <link name="dynamixel_AX12_5_link">
    <!---rviz -->
    <visual>
      <!--link origin is a delta from the joint to the center of the servo box-->
      <origin rpy="0 0 0" xyz="0 0.02 -0.0135"/>
      <geometry>
        <!-- <mesh filename="package://pi_tb_description/meshes/ax12_box.${MESH_EXT}" scale="${M_SCALE} ${M_SCALE} ${M_SCALE}"/> -->
        <box size="0.032 0.04 0.05"/>
      </geometry>
      <material name="Gray">
        <color rgba="0.1 0.1 0.1 1.0"/>
      </material>
    </visual>
  </link>
  <joint name="dynamixel_AX12_5_joint" type="revolute">
    <!--origin of whole dynamixel is at the center of the round part visible on the servo which is the joint -->
    <origin rpy="0 0 0" xyz="0 0 0"/>
    <axis xyz="0 -1 0"/>
    <limit effort="1000" lower="-2.61799166667" upper="2.61799166667" velocity="0.5"/>
    <parent link="dynamixel_AX12_5_link"/>
    <child link="S-B_5_link"/>
  </joint>
  <link name="S-B_5_link">
    <visual>
      <origin rpy="0 0 0" xyz="0 0 0"/>
      <geometry>
        <sphere radius="0.004"/>
      </geometry>
      <material name="Green">
        <color rgba="0 0.5 0 1.0"/>
      </material>
    </visual>
  </link>
  <joint name="S1_5" type="fixed">
    <origin rpy="-1.570795 0 -1.570795 " xyz="0.023 -0.021  0.02"/>
    <parent link="S-B_5_link"/>
    <child link="dynamixel_AX12_7_link"/>
  </joint>
  <link name="dynamixel_AX12_7_link">
    <!---rviz -->
    <visual>
      <!--link origin is a delta from the joint to the center of the servo box-->
      <origin rpy="0 0 0" xyz="0 0.02 -0.0135"/>
      <geometry>
        <!-- <mesh filename="package://pi_tb_description/meshes/ax12_box.${MESH_EXT}" scale="${M_SCALE} ${M_SCALE} ${M_SCALE}"/> -->
        <box size="0.032 0.04 0.05"/>
      </geometry>
      <material name="Gray">
        <color rgba="0.1 0.1 0.1 1.0"/>
      </material>
    </visual>
  </link>
  <joint name="dynamixel_AX12_7_joint" type="revolute">
    <!--origin of whole dynamixel is at the center of the round part visible on the servo which is the joint -->
    <origin rpy="0 0 0" xyz="0 0 0"/>
    <axis xyz="0 -1 0"/>
    <limit effort="1000" lower="-2.61799166667" upper="2.61799166667" velocity="0.5"/>
    <parent link="dynamixel_AX12_7_link"/>
    <child link="S-B_7_link"/>
  </joint>
  <link name="S-B_7_link">
    <visual>
      <origin rpy="0 0 0" xyz="0 0 0"/>
      <geometry>
        <sphere radius="0.004"/>
      </geometry>
      <material name="Green">
        <color rgba="0 0.5 0 1.0"/>
      </material>
    </visual>
  </link>
  <joint name="S1_7" type="fixed">
    <origin rpy="0 0 0" xyz="0 0.021 0.0305"/>
    <parent link="S-B_7_link"/>
    <child link="calf_link_9"/>
  </joint>
  <link name="calf_link_9">
    <visual>
      <origin rpy="0 0 0" xyz="0 0 0"/>
      <geometry>
        <box size="0.024  0.048 0.07"/>
      </geometry>
      <material name="DimWhite">
        <color rgba="0.9 0.9 0.9 1.0"/>
      </material>
    </visual>
  </link>
  <joint name="S1_9" type="fixed">
    <origin rpy="0 3.14159 0" xyz="0 -0.021 0.0305"/>
    <parent link="calf_link_9"/>
    <child link="S-B_9_link"/>
  </joint>
  <link name="S-B_9_link">
    <visual>
      <origin rpy="0 0 0" xyz="0 0 0"/>
      <geometry>
        <sphere radius="0.004"/>
      </geometry>
      <material name="Green">
        <color rgba="0 0.5 0 1.0"/>
      </material>
    </visual>
  </link>
  <joint name="dynamixel_AX12_9_joint" type="revolute">
    <!--origin of whole dynamixel is at the center of the round part visible on the servo which is the joint -->
    <origin rpy="0 0 0" xyz="0 0 0"/>
    <!-- negative green is the joint axis... -->
    <axis xyz="0 -1 0"/>
    <limit effort="1000" lower="-2.61799166667" upper="2.61799166667" velocity="0.5"/>
    <parent link="S-B_9_link"/>
    <child link="dynamixel_AX12_9_link"/>
  </joint>
  <link name="dynamixel_AX12_9_link">
    <!---rviz -->
    <visual>
      <!--link origin is a delta from the joint to the center of the servo box-->
      <origin rpy="0 0 0" xyz="0 0.02 -0.0135"/>
      <geometry>
        <!-- <mesh filename="package://pi_tb_description/meshes/ax12_box.${MESH_EXT}" scale="${M_SCALE} ${M_SCALE} ${M_SCALE}"/> -->
        <box size="0.032 0.04 0.05"/>
      </geometry>
      <material name="black"/>
    </visual>
    <!---gazebo section needs work http://wiki.ros.org/MeshLab http://en.wikipedia.org/wiki/List_of_moment_of_inertia_tensors   
      <inertial>
        <mass value="0.00001" />
        <inertia ixx="1.0" ixy="0.0" ixz="0.0"
          iyy="1.0" iyz="0.0"
          izz="1.0" />
      </inertial>
      <collision>
        <origin xyz="0.0 0.0 -0.0045" rpy="0 0 0" />
        <geometry>
          <box size="0.025 0.038 0.009"/>
        </geometry>
      </collision>
-->
  </link>
  <joint name="robotis_part_10" type="fixed">
    <origin rpy="-1.570795 3.14159 3.14159" xyz="0.039 -0.021 -0.04"/>
    <parent link="dynamixel_AX12_1_link"/>
    <child link="dynamixel_AX12_10_link"/>
  </joint>
  <link name="dynamixel_AX12_10_link">
    <!---rviz -->
    <visual>
      <!--link origin is a delta from the joint to the center of the servo box-->
      <origin rpy="0 0 0" xyz="0 0.02 -0.0135"/>
      <geometry>
        <!-- <mesh filename="package://pi_tb_description/meshes/ax12_box.${MESH_EXT}" scale="${M_SCALE} ${M_SCALE} ${M_SCALE}"/> -->
        <box size="0.032 0.04 0.05"/>
      </geometry>
      <material name="Gray">
        <color rgba="0.1 0.1 0.1 1.0"/>
      </material>
    </visual>
  </link>
  <joint name="dynamixel_AX12_10_joint" type="revolute">
    <!--origin of whole dynamixel is at the center of the round part visible on the servo which is the joint -->
    <origin rpy="0 0 0" xyz="0 0 0"/>
    <axis xyz="0 -1 0"/>
    <limit effort="1000" lower="-2.61799166667" upper="2.61799166667" velocity="0.5"/>
    <parent link="dynamixel_AX12_10_link"/>
    <child link="S-B_10_link"/>
  </joint>
  <link name="S-B_10_link">
    <visual>
      <origin rpy="0 0 0" xyz="0 0 0"/>
      <geometry>
        <sphere radius="0.004"/>
      </geometry>
      <material name="Green">
        <color rgba="0 0.5 0 1.0"/>
      </material>
    </visual>
  </link>
  <joint name="S1_10" type="fixed">
    <origin rpy="-1.570795 0 -1.570795 " xyz="0.023 -0.021  0.02"/>
    <parent link="S-B_10_link"/>
    <child link="dynamixel_AX12_12_link"/>
  </joint>
  <link name="dynamixel_AX12_12_link">
    <!---rviz -->
    <visual>
      <!--link origin is a delta from the joint to the center of the servo box-->
      <origin rpy="0 0 0" xyz="0 0.02 -0.0135"/>
      <geometry>
        <!-- <mesh filename="package://pi_tb_description/meshes/ax12_box.${MESH_EXT}" scale="${M_SCALE} ${M_SCALE} ${M_SCALE}"/> -->
        <box size="0.032 0.04 0.05"/>
      </geometry>
      <material name="Gray">
        <color rgba="0.1 0.1 0.1 1.0"/>
      </material>
    </visual>
  </link>
  <joint name="dynamixel_AX12_12_joint" type="revolute">
    <!--origin of whole dynamixel is at the center of the round part visible on the servo which is the joint -->
    <origin rpy="0 0 0" xyz="0 0 0"/>
    <axis xyz="0 -1 0"/>
    <limit effort="1000" lower="-2.61799166667" upper="2.61799166667" velocity="0.5"/>
    <parent link="dynamixel_AX12_12_link"/>
    <child link="S-B_12_link"/>
  </joint>
  <link name="S-B_12_link">
    <visual>
      <origin rpy="0 0 0" xyz="0 0 0"/>
      <geometry>
        <sphere radius="0.004"/>
      </geometry>
      <material name="Green">
        <color rgba="0 0.5 0 1.0"/>
      </material>
    </visual>
  </link>
  <joint name="S1_12" type="fixed">
    <origin rpy="0 0 0" xyz="0 0.021 0.0305"/>
    <parent link="S-B_12_link"/>
    <child link="calf_link_14"/>
  </joint>
  <link name="calf_link_14">
    <visual>
      <origin rpy="0 0 0" xyz="0 0 0"/>
      <geometry>
        <box size="0.024  0.048 0.07"/>
      </geometry>
      <material name="DimWhite">
        <color rgba="0.9 0.9 0.9 1.0"/>
      </material>
    </visual>
  </link>
  <joint name="S1_14" type="fixed">
    <origin rpy="0 3.14159 0" xyz="0 -0.021 0.0305"/>
    <parent link="calf_link_14"/>
    <child link="S-B_14_link"/>
  </joint>
  <link name="S-B_14_link">
    <visual>
      <origin rpy="0 0 0" xyz="0 0 0"/>
      <geometry>
        <sphere radius="0.004"/>
      </geometry>
      <material name="Green">
        <color rgba="0 0.5 0 1.0"/>
      </material>
    </visual>
  </link>
  <joint name="dynamixel_AX12_14_joint" type="revolute">
    <!--origin of whole dynamixel is at the center of the round part visible on the servo which is the joint -->
    <origin rpy="0 0 0" xyz="0 0 0"/>
    <!-- negative green is the joint axis... -->
    <axis xyz="0 -1 0"/>
    <limit effort="1000" lower="-2.61799166667" upper="2.61799166667" velocity="0.5"/>
    <parent link="S-B_14_link"/>
    <child link="dynamixel_AX12_14_link"/>
  </joint>
  <link name="dynamixel_AX12_14_link">
    <!---rviz -->
    <visual>
      <!--link origin is a delta from the joint to the center of the servo box-->
      <origin rpy="0 0 0" xyz="0 0.02 -0.0135"/>
      <geometry>
        <!-- <mesh filename="package://pi_tb_description/meshes/ax12_box.${MESH_EXT}" scale="${M_SCALE} ${M_SCALE} ${M_SCALE}"/> -->
        <box size="0.032 0.04 0.05"/>
      </geometry>
      <material name="black"/>
    </visual>
    <!---gazebo section needs work http://wiki.ros.org/MeshLab http://en.wikipedia.org/wiki/List_of_moment_of_inertia_tensors   
      <inertial>
        <mass value="0.00001" />
        <inertia ixx="1.0" ixy="0.0" ixz="0.0"
          iyy="1.0" iyz="0.0"
          izz="1.0" />
      </inertial>
      <collision>
        <origin xyz="0.0 0.0 -0.0045" rpy="0 0 0" />
        <geometry>
          <box size="0.025 0.038 0.009"/>
        </geometry>
      </collision>
-->
  </link>
</robot>

