<?xml version="1.0" ?>
<!-- =================================================================================== -->
<!-- |    This document was autogenerated by xacro from front_right_leg.xacro          | -->
<!-- |    EDITING THIS FILE BY HAND IS NOT RECOMMENDED                                 | -->
<!-- =================================================================================== -->
<robot name="dog_picker" xmlns:xacro="http://www.ros.org/wiki/xacro">
  <!-- negative green is the joint axis in y... -->
  <!-- z is blue and x is red... -->
  <link name="base_link">
    <visual>
      <origin rpy="0 0 0" xyz="0 0 0.150"/>
      <geometry>
        <box size="0.09 0.1 0.032"/>
      </geometry>
      <material name="DimWhite">
        <color rgba="0.9 0.9 0.9 1.0"/>
      </material>
    </visual>
  </link>
  <joint name="robotis_part_4" type="fixed">
    <origin rpy="1.570795 -1.570795 0.0" xyz="0.045 -0.0365 0.111"/>
    <parent link="base_link"/>
    <child link="dynamixel_AX12_4_link"/>
  </joint>
  <link name="dynamixel_AX12_4_link">
    <!---rviz -->
    <visual>
      <!--link origin is a delta from the joint to the center of the servo box-->
      <origin rpy="0 0 0" xyz="0 0.02 -0.0135"/>
      <geometry>
        <!-- <mesh filename="package://pi_tb_description/meshes/ax12_box.${MESH_EXT}" scale="${M_SCALE} ${M_SCALE} ${M_SCALE}"/> -->
        <box size="0.032 0.04 0.05"/>
      </geometry>
      <material name="Gray">
        <color rgba="0.1 0.1 0.1 1.0"/>
      </material>
    </visual>
  </link>
  <joint name="dynamixel_AX12_4_joint" type="revolute">
    <!--origin of whole dynamixel is at the center of the round part visible on the servo which is the joint -->
    <origin rpy="0 0 0" xyz="0 0 0"/>
    <axis xyz="0 -1 0"/>
    <limit effort="1000" lower="-2.61799166667" upper="2.61799166667" velocity="0.5"/>
    <parent link="dynamixel_AX12_4_link"/>
    <child link="S-B_4_link"/>
  </joint>
  <link name="S-B_4_link">
    <visual>
      <origin rpy="0 0 0" xyz="0 0 0"/>
      <geometry>
        <sphere radius="0.004"/>
      </geometry>
      <material name="Green">
        <color rgba="0 0.5 0 1.0"/>
      </material>
    </visual>
  </link>
  <joint name="S1_4" type="fixed">
    <origin rpy="-1.570795 0 1.570795 " xyz="-0.023 -0.021  0.02"/>
    <parent link="S-B_4_link"/>
    <child link="dynamixel_AX12_16_link"/>
  </joint>
  <link name="dynamixel_AX12_16_link">
    <!---rviz -->
    <visual>
      <!--link origin is a delta from the joint to the center of the servo box-->
      <origin rpy="0 0 0" xyz="0 0.02 -0.0135"/>
      <geometry>
        <!-- <mesh filename="package://pi_tb_description/meshes/ax12_box.${MESH_EXT}" scale="${M_SCALE} ${M_SCALE} ${M_SCALE}"/> -->
        <box size="0.032 0.04 0.05"/>
      </geometry>
      <material name="Gray">
        <color rgba="0.1 0.1 0.1 1.0"/>
      </material>
    </visual>
  </link>
  <joint name="dynamixel_AX12_16_joint" type="revolute">
    <!--origin of whole dynamixel is at the center of the round part visible on the servo which is the joint -->
    <origin rpy="0 0 0" xyz="0 0 0"/>
    <axis xyz="0 -1 0"/>
    <limit effort="1000" lower="-2.61799166667" upper="2.61799166667" velocity="0.5"/>
    <parent link="dynamixel_AX12_16_link"/>
    <child link="S-B_16_link"/>
  </joint>
  <link name="S-B_16_link">
    <visual>
      <origin rpy="0 0 0" xyz="0 0 0"/>
      <geometry>
        <sphere radius="0.004"/>
      </geometry>
      <material name="Green">
        <color rgba="0 0.5 0 1.0"/>
      </material>
    </visual>
  </link>
  <joint name="S1_16" type="fixed">
    <origin rpy="0 0 0" xyz="0 0.021 0.0305"/>
    <parent link="S-B_16_link"/>
    <child link="calf_link_8"/>
  </joint>
  <link name="calf_link_8">
    <visual>
      <origin rpy="0 0 0" xyz="0 0 0"/>
      <geometry>
        <box size="0.024  0.048 0.07"/>
      </geometry>
      <material name="DimWhite">
        <color rgba="0.9 0.9 0.9 1.0"/>
      </material>
    </visual>
  </link>
  <joint name="S1_8" type="fixed">
    <origin rpy="0 3.14159 0" xyz="0 -0.021 0.0305"/>
    <parent link="calf_link_8"/>
    <child link="S-B_8_link"/>
  </joint>
  <link name="S-B_8_link">
    <visual>
      <origin rpy="0 0 0" xyz="0 0 0"/>
      <geometry>
        <sphere radius="0.004"/>
      </geometry>
      <material name="Green">
        <color rgba="0 0.5 0 1.0"/>
      </material>
    </visual>
  </link>
  <joint name="dynamixel_AX12_8_joint" type="revolute">
    <!--origin of whole dynamixel is at the center of the round part visible on the servo which is the joint -->
    <origin rpy="0 0 0" xyz="0 0 0"/>
    <!-- negative green is the joint axis... -->
    <axis xyz="0 -1 0"/>
    <limit effort="1000" lower="-2.61799166667" upper="2.61799166667" velocity="0.5"/>
    <parent link="S-B_8_link"/>
    <child link="dynamixel_AX12_8_link"/>
  </joint>
  <link name="dynamixel_AX12_8_link">
    <!---rviz -->
    <visual>
      <!--link origin is a delta from the joint to the center of the servo box-->
      <origin rpy="0 0 0" xyz="0 0.02 -0.0135"/>
      <geometry>
        <!-- <mesh filename="package://pi_tb_description/meshes/ax12_box.${MESH_EXT}" scale="${M_SCALE} ${M_SCALE} ${M_SCALE}"/> -->
        <box size="0.032 0.04 0.05"/>
      </geometry>
      <material name="black"/>
    </visual>
    <!---gazebo section needs work http://wiki.ros.org/MeshLab http://en.wikipedia.org/wiki/List_of_moment_of_inertia_tensors   
      <inertial>
        <mass value="0.00001" />
        <inertia ixx="1.0" ixy="0.0" ixz="0.0"
          iyy="1.0" iyz="0.0"
          izz="1.0" />
      </inertial>
      <collision>
        <origin xyz="0.0 0.0 -0.0045" rpy="0 0 0" />
        <geometry>
          <box size="0.025 0.038 0.009"/>
        </geometry>
      </collision>
-->
  </link>
</robot>

